Workbook

Sheet DATA_DICTIONARY
A1: Column Name | B1: Description | C1: Notes
A2: Transaction_ID | B2: Unique identifier for each transaction (T001–T200) | C2: Primary key
A3: Date | B3: Date of transaction in DD/MM/YYYY format | C3: 2024 only
A4: Customer_ID | B4: Links to CUSTOMER_PROFILES sheet (CUST001–CUST030) | C4: Foreign key
A5: Transaction_Type | B5: Type: Salary Credit, Cash Deposit, Wire Transfer, Bill Payment etc | C5: Categorisation
A6: Amount_GBP | B6: Transaction amount in British Pounds Sterling | C6: Always positive
A7: Currency | B7: Transaction currency — GBP for domestic, others for international | C7: ISO code
A8: Counterparty_Name | B8: Name of the other party in the transaction | C8: For TM rules
A9: Counterparty_Country | B9: Country of the counterparty | C9: Used in Rule 3 FATF check
A10: Counterparty_Bank | B10: Bank used by the counterparty | C10: For investigation
A11: Direction | B11: Credit = money in, Debit = money out | C11: Always Credit or Debit
A12: Running_Balance | B12: Customer account balance after transaction | C12: Running total
... A15: Alert_ID | B15: Alert reference number — links to ALERT_INVESTIGATION_LOG | C15: ALT001–ALT010

Sheet CUSTOMER_PROFILES
A1: Customer_ID | B1: Customer_Type | C1: Nationality | D1: Country_of_Residence | E1: Occupation | F1: Risk_Rating | G1: KYC_Tier | H1: Monthly_Expected_Turnover_GBP | I1: Account_Status | J1: Account_Open_Date
A2: CUST001 | B2: Individual | C2: British | D2: UK | E2: Teacher | F2: Low | G2: =INDEX(KYC_CDD_FRAMEWORK!$K$30:$K$59,MATCH(A2,KYC_CDD_FRAMEWORK!$A$30:$A$59,0)) -> SDD | H2: 3500 | I2: Active | J2: 43466
A3: CUST002 | B3: Individual | C3: British | D3: UK | E3: Nurse | F3: Low | G3: =INDEX(KYC_CDD_FRAMEWORK!$K$30:$K$59,MATCH(A3,KYC_CDD_FRAMEWORK!$A$30:$A$59,0)) -> SDD | H3: 3200 | I3: Active | J3: 43174
A4: CUST003 | B4: Individual | C4: British | D4: UK | E4: Engineer | F4: Low | G4: =INDEX(KYC_CDD_FRAMEWORK!$K$30:$K$59,MATCH(A4,KYC_CDD_FRAMEWORK!$A$30:$A$59,0)) -> SDD | H4: 5500 | I4: Active | J4: 42906
A5: CUST004 | B5: Individual | C5: British | D5: UK | E5: Accountant | F5: Low | G5: =INDEX(KYC_CDD_FRAMEWORK!$K$30:$K$59,MATCH(A5,KYC_CDD_FRAMEWORK!$A$30:$A$59,0)) -> SDD | H5: 6000 | I5: Active | J5: 43840
A6: CUST005 | B6: Individual | C6: British | D6: UK | E6: Police Officer | F6: Low | G6: =INDEX(KYC_CDD_FRAMEWORK!$K$30:$K$59,MATCH(A6,KYC_CDD_FRAMEWORK!$A$30:$A$59,0)) -> SDD | H6: 3800 | I6: Active | J6: 43651
A7: CUST006 | B7: Individual | C7: British | D7: UK | E7: Retail Manager | F7: Low | G7: =INDEX(KYC_CDD_FRAMEWORK!$K$30:$K$59,MATCH(A7,KYC_CDD_FRAMEWORK!$A$30:$A$59,0)) -> SDD | H7: 3000 | I7: Active | J7: 43365
A8: CUST007 | B8: Individual | C8: British | D8: UK | E8: IT Analyst | F8: Low | G8: =INDEX(KYC_CDD_FRAMEWORK!$K$30:$K$59,MATCH(A8,KYC_CDD_FRAMEWORK!$A$30:$A$59,0)) -> CDD | H8: 4500 | I8: Active | J8: 43875
A9: CUST008 | B9: Individual | C9: British | D9: UK | E9: Social Worker | F9: Low | G9: =INDEX(KYC_CDD_FRAMEWORK!$K$30:$K$59,MATCH(A9,KYC_CDD_FRAMEWORK!$A$30:$A$59,0)) -> SDD | H9: 3300 | I9: Active | J9: 43069
A10: CUST009 | B10: Individual | C10: British | D10: UK | E10: Pharmacist | F10: Low | G10: =INDEX(KYC_CDD_FRAMEWORK!$K$30:$K$59,MATCH(A10,KYC_CDD_FRAMEWORK!$A$30:$A$59,0)) -> SDD | H10: 5000 | I10: Active | J10: 43563
A11: CUST010 | B11: Individual | C11: British | D11: UK | E11: Electrician | F11: Low | G11: =INDEX(KYC_CDD_FRAMEWORK!$K$30:$K$59,MATCH(A11,KYC_CDD_FRAMEWORK!$A$30:$A$59,0)) -> SDD | H11: 4000 | I11: Active | J11: 43329
A12: CUST011 | B12: Individual | C12: Indian | D12: UK | E12: IT Consultant | F12: Medium | G12: =INDEX(KYC_CDD_FRAMEWORK!$K$30:$K$59,MATCH(A12,KYC_CDD_FRAMEWORK!$A$30:$A$59,0)) -> CDD | H12: 7000 | I12: Active | J12: 43891
A13: CUST012 | B13: Individual | C13: Nigerian | D13: UK | E13: Import/Export | F13: Medium | G13: =INDEX(KYC_CDD_FRAMEWORK!$K$30:$K$59,MATCH(A13,KYC_CDD_FRAMEWORK!$A$30:$A$59,0)) -> EDD | H13: 12000 | I13: Active | J13: 43631
... A31: CUST030 | B31: Corporate | C31: UK Registered | D31: UK | E31: Import/Export Ltd | F31: Medium | G31: =INDEX(KYC_CDD_FRAMEWORK!$K$30:$K$59,MATCH(A31,KYC_CDD_FRAMEWORK!$A$30:$A$59,0)) -> CDD | H31: 75000 | I31: Active | J31: 43174

Sheet TRANSACTION_LEDGER
A1: Transaction_ID | B1: Date | C1: Customer_ID | D1: Transaction_Type | E1: Amount_GBP | F1: Currency | G1: Counterparty_Name | H1: Counterparty_Country | I1: Counterparty_Bank | J1: Direction | K1: Running_Balance | L1: Flagged | M1: Flag_Reason | N1: Alert_ID
A2: T001 | B2: 45292 | C2: CUST001 | D2: Salary Credit | E2: 3500 | F2: GBP | G2: City Council | H2: UK | I2: Barclays | J2: Credit | K2: 3500 | L2: NO
A3: T004 | B3: 45292 | C3: CUST002 | D3: Salary Credit | E3: 3200 | F3: GBP | G3: NHS | H3: UK | I3: Lloyds | J3: Credit | K3: 3200 | L3: NO
A4: T006 | B4: 45292 | C4: CUST003 | D4: Salary Credit | E4: 5500 | F4: GBP | G4: Tech Corp | H4: UK | I4: HSBC | J4: Credit | K4: 5500 | L4: NO
A5: T008 | B5: 45292 | C5: CUST004 | D5: Salary Credit | E5: 6000 | F5: GBP | G5: Deloitte | H5: UK | I5: NatWest | J5: Credit | K5: 6000 | L5: NO
A6: T010 | B6: 45292 | C6: CUST005 | D6: Salary Credit | E6: 3800 | F6: GBP | G6: Police Scotland | H6: UK | I6: RBS | J6: Credit | K6: 3800 | L6: NO
A7: T066 | B7: 45292 | C7: CUST006 | D7: Salary Credit | E7: 3000 | F7: GBP | G7: Tesco | H7: UK | I7: Santander | J7: Credit | K7: 3000 | L7: NO
A8: T067 | B8: 45292 | C8: CUST007 | D8: Salary Credit | E8: 4500 | F8: GBP | G8: IBM | H8: UK | I8: HSBC | J8: Credit | K8: 4500 | L8: NO
A9: T068 | B9: 45292 | C9: CUST008 | D9: Salary Credit | E9: 3300 | F9: GBP | G9: Social Services | H9: UK | I9: Barclays | J9: Credit | K9: 3300 | L9: NO
A10: T069 | B10: 45292 | C10: CUST009 | D10: Salary Credit | E10: 5000 | F10: GBP | G10: Boots Pharmacy | H10: UK | I10: Lloyds | J10: Credit | K10: 5000 | L10: NO
A11: T070 | B11: 45292 | C11: CUST010 | D11: Salary Credit | E11: 4000 | F11: GBP | G11: Construction Co | H11: UK | I11: NatWest | J11: Credit | K11: 4000 | L11: NO
A12: T002 | B12: 45296 | C12: CUST001 | D12: Bill Payment | E12: 850 | F12: GBP | G12: British Gas | H12: UK | I12: Barclays | J12: Debit | K12: 2650 | L12: NO
A13: T005 | B13: 45297 | C13: CUST002 | D13: Bill Payment | E13: 750 | F13: GBP | G13: Landlord | H13: UK | I13: Lloyds | J13: Debit | K13: 2450 | L13: NO
... A45: T090 | B45: 45352 | C45: CUST011 | D45: Business Income | E45: 7000 | F45: GBP | G45: Various Clients | H45: UK | I45: HSBC | J45: Credit | K45: 7000 | L45: NO
A46: T051 | B46: 45354 | C46: CUST018 | D46: Cash Deposit | E46: 9500 | F46: GBP | G46: Cash | H46: UK | I46: Branch | J46: Credit | K46: 9500 | L46: YES | M46: STRUCTURING | N46: ALT001
A47: T052 | B47: 45355 | C47: CUST018 | D47: Cash Deposit | E47: 9200 | F47: GBP | G47: Cash | H47: UK | I47: Branch | J47: Credit | K47: 18700 | L47: YES | M47: STRUCTURING | N47: ALT001
A48: T019 | B48: 45356 | C48: CUST006 | D48: Bill Payment | E48: 600 | F48: GBP | G48: Landlord | H48: UK | I48: Santander | J48: Debit | K48: 2400 | L48: NO
A49: T091 | B49: 45356 | C49: CUST016 | D49: Salary Credit | E49: 4500 | F49: GBP | G49: Construction Ltd | H49: UK | I49: Barclays | J49: Credit | K49: 4500 | L49: NO
A50: T053 | B50: 45358 | C50: CUST018 | D50: Cash Deposit | E50: 9800 | F50: GBP | G50: Cash | H50: UK | I50: Branch | J50: Credit | K50: 28500 | L50: YES | M50: STRUCTURING | N50: ALT001
A51: T092 | B51: 45361 | C51: CUST017 | D51: Business Income | E51: 20000 | F51: GBP | G51: Transfer Clients | H51: UK | I51: Barclays | J51: Credit | K51: 20000 | L51: NO
A52: T093 | B52: 45366 | C52: CUST019 | D52: Business Income | E52: 50000 | F52: GBP | G52: Property Sales | H52: UK | I52: HSBC | J52: Credit | K52: 50000 | L52: NO
A53: T094 | B53: 45371 | C53: CUST020 | D53: Salary Credit | E53: 30000 | F53: GBP | G53: Consultancy Co | H53: UK | I53: Barclays | J53: Credit | K53: 30000 | L53: NO
A54: T095 | B54: 45376 | C54: CUST021 | D54: Salary Credit | E54: 15000 | F54: GBP | G54: Council | H54: UK | I54: NatWest | J54: Credit | K54: 15000 | L54: NO
A55: T021 | B55: 45383 | C55: CUST008 | D55: Salary Credit | E55: 3300 | F55: GBP | G55: Social Services | H55: UK | I55: Barclays | J55: Credit | K55: 3300 | L55: NO
A56: T023 | B56: 45383 | C56: CUST009 | D56: Salary Credit | E56: 5000 | F56: GBP | G56: Boots Pharmacy | H56: UK | I56: Lloyds | J56: Credit | K56: 5000 | L56: NO
A57: T025 | B57: 45383 | C57: CUST010 | D57: Salary Credit | E57: 4000 | F57: GBP | G57: Construction Co | H57: UK | I57: NatWest | J57: Credit | K57: 4000 | L57: NO
A58: T096 | B58: 45383 | C58: CUST001 | D58: Salary Credit | E58: 3500 | F58: GBP | G58: City Council | H58: UK | I58: Barclays | J58: Credit | K58: 3500 | L58: NO
A59: T097 | B59: 45383 | C59: CUST002 | D59: Salary Credit | E59: 3200 | F59: GBP | G59: NHS | H59: UK | I59: Lloyds | J59: Credit | K59: 3200 | L59: NO
A60: T098 | B60: 45383 | C60: CUST003 | D60: Salary Credit | E60: 5500 | F60: GBP | G60: Tech Corp | H60: UK | I60: HSBC | J60: Credit | K60: 5500 | L60: NO
A61: T099 | B61: 45383 | C61: CUST005 | D61: Salary Credit | E61: 3800 | F61: GBP | G61: Police Scotland | H61: UK | I61: RBS | J61: Credit | K61: 3800 | L61: NO
A62: T100 | B62: 45383 | C62: CUST006 | D62: Salary Credit | E62: 3000 | F62: GBP | G62: Tesco | H62: UK | I62: Santander | J62: Credit | K62: 3000 | L62: NO
... A66: T102 | B66: 45392 | C66: CUST012 | D66: Bill Payment | E66: 3000 | F66: GBP | G66: Warehouse | H66: UK | I66: Barclays | J66: Debit | K66: 9000 | L66: NO
A67: T054 | B67: 45397 | C67: CUST007 | D67: Wire Transfer IN | E67: 45000 | F67: GBP | G67: Al Maktoum Trading | H67: UAE | I67: Emirates NBD | J67: Credit | K67: 45000 | L67: YES | M67: RAPID IN-OUT | N67: ALT002
A68: T103 | B68: 45397 | C68: CUST013 | D68: Bill Payment | E68: 1200 | F68: GBP | G68: Supplier | H68: UK | I68: NatWest | J68: Debit | K68: 13800 | L68: NO
A69: T055 | B69: 45398 | C69: CUST007 | D69: Wire Transfer OUT | E69: 44500 | F69: GBP | G69: Baltik UAB | H69: Lithuania | I69: SEB Bank | J69: Debit | K69: 500 | L69: YES | M69: RAPID IN-OUT | N69: ALT002
A70: T104 | B70: 45402 | C70: CUST014 | D70: Mortgage Payment | E70: 8000 | F70: GBP | G70: Santander | H70: UK | I70: HSBC | J70: Debit | K70: 17000 | L70: NO
A71: T105 | B71: 45410 | C71: CUST015 | D71: Cash Deposit | E71: 3500 | F71: GBP | G71: Cash | H71: UK | I71: Branch | J71: Credit | K71: 3500 | L71: NO
A72: T026 | B72: 45413 | C72: CUST001 | D72: Salary Credit | E72: 3500 | F72: GBP | G72: City Council | H72: UK | I72: Barclays | J72: Credit | K72: 3500 | L72: NO
A73: T027 | B73: 45413 | C73: CUST002 | D73: Salary Credit | E73: 3200 | F73: GBP | G73: NHS | H73: UK | I73: Lloyds | J73: Credit | K73: 3200 | L73: NO
A74: T028 | B74: 45413 | C74: CUST003 | D74: Salary Credit | E74: 5500 | F74: GBP | G74: Tech Corp | H74: UK | I74: HSBC | J74: Credit | K74: 5500 | L74: NO
...

Sheet ALERT_INVESTIGATION_LOG
A1: CALEDONIA BANK PLC — ALERT INVESTIGATION LOG
A2: Regulatory framework: MLR 2017 | JMLSG 2026 | POCA 2002 | FCA Financial Crime Guide | All alerts FY2024
A4: ALERT_ID | B4: DATE_RAISED | C4: CUSTOMER_ID | D4: OCCUPATION | E4: ALERT_TYPE | F4: TM_RULE_TRIGGERED | G4: TRANSACTION_REF | H4: AMOUNT_GBP | I4: PRIORITY | J4: ASSIGNED_TO | K4: DATE_CLOSED | L4: DISPOSITION | M4: SAR_FILED | N4: NOTES
A5: ALT001 | B5: 45358 | C5: CUST018 | D5: Market Trader | E5: Structuring | F5: TM-001 | G5: T051, T052, T053 | H5: 28500 | I5: HIGH | J5: AML Analyst | K5: 45366 | L5: TRUE POSITIVE | M5: YES | N5: 3 cash deposits £9,500/£9,200/£9,800 in 5 days. 356% of monthly turnover. SAR filed.
A6: ALT002 | B6: 45398 | C6: CUST007 | D6: IT Analyst | E6: Rapid In-Out | F6: TM-002 | G6: T054, T055 | H6: 45000 | I6: HIGH | J6: AML Analyst | K6: 45407 | L6: TRUE POSITIVE | M6: YES | N6: £45,000 in from UAE, £44,500 out to Lithuania within 24hrs. 98.9% pass-through. SAR filed.
A7: ALT003 | B7: 45434 | C7: CUST012 | D7: Import/Export | E7: High Risk Jurisdiction | F7: TM-003 | G7: T056 | H7: 28000 | I7: HIGH | J7: AML Analyst | K7: 45442 | L7: TRUE POSITIVE | M7: YES | N7: SWIFT transfer to Tehran Trading Co, Iran. FATF high-risk jurisdiction. SAR filed.
A8: ALT004 | B8: 45453 | C8: CUST025 | D8: Jewellery Trader | E8: Dormant Account Activity | F8: TM-004 | G8: T057, T058 | H8: 75000 | I8: HIGH | J8: AML Analyst | K8: 45463 | L8: TRUE POSITIVE | M8: YES | N8: Account dormant 3+ years. £75,000 credit from unknown source. Immediate layering detected. SAR filed.
A9: ALT005 | B9: 45491 | C9: CUST021 | D9: Local Council Leader | E9: PEP High Value | F9: TM-005 | G9: T059 | H9: 120000 | I9: HIGH | J9: AML Analyst | L9: PENDING | M9: NO | N9: PEP received £120,000 from Cayman Islands offshore entity. EDD review ongoing. Awaiting senior management approval.
A10: ALT006 | B10: 45513 | C10: CUST022 | D10: Import/Export | E10: Round Tripping | F10: TM-007 | G10: T060, T061 | H10: 30000 | I10: HIGH | J10: AML Analyst | K10: 45524 | L10: FALSE POSITIVE | M10: NO | N10: Funds returned between linked accounts — confirmed legitimate loan repayment between family members. Documented and closed.
A11: ALT007 | B11: 45549 | C11: CUST015 | D11: Market Trader | E11: Cash Intensity | F11: TM-006 | G11: T062 | H11: 18000 | I11: MEDIUM | J11: AML Analyst | K11: 45560 | L11: FALSE POSITIVE | M11: NO | N11: Cash deposit 225% of monthly turnover. Customer provided market trading invoices and receipts. Legitimate seasonal income.
A12: ALT008 | B12: 45586 | C12: CUST028 | D12: Logistics Manager | E12: Sanctions Screening | F12: TM-008 | G12: T063, T064 | H12: 23500 | I12: CRITICAL | J12: AML Analyst | K12: 45616 | L12: TRUE POSITIVE | M12: YES | N12: SWIFT transfers to Russia and Belarus — OFSI sanctioned jurisdictions. Account frozen immediately. MLRO notified within 2 hours. SAR filed same day.
A13: ALT009 | B13: 45599 | C13: CUST015 | D13: Market Trader | E13: Structuring | F13: TM-001 | G13: T065 | H13: 9700 | I13: MEDIUM | J13: AML Analyst | K13: 45608 | L13: WHITELISTED | M13: NO | N13: Single cash deposit £9,700. Reviewed in context of ALT007 — consistent with seasonal trading pattern. Whitelisted with 6-month review.
A14: ALT010 | B14: 45656 | C14: CUST029 | D14: Holding Company | E14: Complex Corporate Structure | F14: TM-009 | G14: T198, T199 | H14: 100000 | I14: HIGH | J14: AML Analyst | L14: PENDING | M14: NO | N14: £100,000 corporate credit followed by £50,000 intercompany transfer. Complex ownership structure under review. UBO verification outstanding.
A17: ALERT DISPOSITION SUMMARY — FY2024
A18: KEY METRICS | E18: PRIORITY BREAKDOWN | I18: SAR METRICS
A19: Total Alerts Reviewed | C19: =COUNTA(A5:A14) -> 10 | E19: CRITICAL | F19: =COUNTIF(I5:I14,"CRITICAL") -> 1 | I19: Total SARs Filed | K19: =COUNTIF(M5:M14,"YES") -> 5
A20: True Positives | C20: =COUNTIF(L5:L14,"TRUE POSITIVE") -> 5 | E20: HIGH | F20: =COUNTIF(I5:I14,"HIGH") -> 7 | I20: SAR Filing Rate | K20: =COUNTIF(M5:M14,"YES")/COUNTA(M5:M14) -> 0.5
A21: False Positives | C21: =COUNTIF(L5:L14,"FALSE POSITIVE") -> 2 | E21: MEDIUM | F21: =COUNTIF(I5:I14,"MEDIUM") -> 2 | I21: Avg Days to Close | K21: =AVERAGEIF(L5:L14,"TRUE POSITIVE",K5:K14)-AVERAGEIF(L5:L14,"TRUE POSITIVE",B5:B14) -> 13
A22: Pending Investigation | C22: =COUNTIF(L5:L14,"PENDING") -> 2 | I22: Sanctions SARs | K22: =COUNTIF(E5:E14,"Sanctions Screening") -> 1
A23: Whitelisted | C23: =COUNTIF(L5:L14,"WHITELISTED") -> 1
A24: SARs Filed | C24: =COUNTIF(M5:M14,"YES") -> 5
A25: False Positive Rate | C25: =COUNTIF(L5:L14,"FALSE POSITIVE")/COUNTA(L5:L14) -> 0.2
A26: Critical Alerts | C26: =COUNTIF(I5:I14,"CRITICAL") -> 1
A30: TRUE POSITIVE | B30: =COUNTIF(L5:L14,"TRUE POSITIVE") -> 5
A31: FALSE POSITIVE | B31: =COUNTIF(L5:L14,"FALSE POSITIVE") -> 2
A32: PENDING | B32: =COUNTIF(L5:L14,"PENDING") -> 2
A33: WHITELISTED | B33: =COUNTIF(L5:L14,"WHITELISTED") -> 1
A49: Note: False Positive Rate of 20% is within acceptable industry range (15-25%). SAR filing rate of 50% reflects conservative approach aligned to JMLSG 2026 guidance. All SARs submitted to NCA within 7 working days per POCA 2002 Section 330.

Sheet KYC_CDD_FRAMEWORK
A1: CALEDONIA BANK PLC — KYC/CDD RISK ASSESSMENT FRAMEWORK
A2: Regulatory basis: MLR 2017 Regulations 28, 33 & 40 | JMLSG Guidance 2026 Part I Chapter 5 | FCA Financial Crime Guide
A4: SECTION 1 — CDD TIER DEFINITIONS
A5: CDD TIER | B5: REGULATORY BASIS | C5: CUSTOMER TYPE | D5: REVIEW FREQUENCY | E5: KEY REQUIREMENTS
A6: SDD (Simplified Due Diligence) | B6: MLR 2017 Reg 37 | C6: UK/EEA regulated firms, listed companies, public authorities, and low-risk retail customers scoring ≤ 20 points | D6: 3 years | E6: Verify entity type, confirm regulatory status, no source of funds required
A7: CDD (Customer Due Diligence) | B7: MLR 2017 Reg 28 | C7: Standard retail and business customers | D7: 1-2 years | E7: Photo ID, proof of address, source of funds for transactions >£10,000
A8: EDD (Enhanced Due Diligence) | B8: MLR 2017 Reg 33 | C8: PEPs, high-risk countries, complex structures, cash-intensive | D8: 6 months | E8: Source of wealth, senior management approval, ongoing monitoring, adverse media
A10: SECTION 2 — CUSTOMER RISK SCORING MODEL
A11: Total score out of 100 points across 5 risk dimensions. Higher score = higher risk. Score determines CDD tier assignment.
A12: RISK DIMENSION | B12: MAX SCORE | C12: SCORING CRITERIA | D12: WEIGHT
A13: Country Risk | B13: 30 | C13: UK/EEA = 0-5pts, Standard = 6-15pts, FATF Grey List = 16-25pts, FATF High Risk = 26-30pts | D13: 0.3
A14: Customer Type | B14: 25 | C14: Salaried individual = 0-5pts, Self-employed = 6-15pts, PEP/HNW = 16-22pts, Cash business = 23-25pts | D14: 0.25
A15: Product Risk | B15: 20 | C15: Standard current account = 0-5pts, Business account = 6-12pts, International payments = 13-17pts, Private banking = 18-20pts | D15: 0.2
A16: Transaction Behaviour | B16: 15 | C16: Expected pattern = 0-3pts, Minor anomalies = 4-8pts, Significant anomalies = 9-12pts, Structuring/layering = 13-15pts | D16: 0.15
A17: Adverse Information | B17: 10 | C17: None = 0pts, Minor = 1-4pts, Significant = 5-7pts, Sanctions/PEP/Criminal = 8-10pts | D17: 0.1
A18: TOTAL | B18: 100 | D18: 1
A20: SECTION 3 — CDD TIER ASSIGNMENT
A21: TOTAL SCORE RANGE | B21: CDD TIER | C21: RISK LEVEL | D21: ACTION REQUIRED
A22: 0 — 20 | B22: SDD | C22: LOW | D22: Simplified Due Diligence. 3-year review. Confirm regulated status only.
A23: 21 — 50 | B23: CDD | C23: MEDIUM | D23: Standard Customer Due Diligence. Annual review. Photo ID and proof of address.
A24: 51 — 75 | B24: EDD | C24: HIGH | D24: Enhanced Due Diligence required. 6-monthly review. Source of wealth mandatory.
A25: 76 — 100 | B25: EDD Urgent | C25: CRITICAL | D25: Immediate senior management review. Consider account closure. File SAR if suspicious.
A27: SECTION 4 — CUSTOMER RISK REGISTER
A28: Risk scores applied to all 30 Caledonia Bank customers. CDD tier assigned based on Section 3 scoring model.
A29: CUSTOMER_ID | B29: CUSTOMER_NAME | C29: NATIONALITY | D29: OCCUPATION | E29: COUNTRY RISK | F29: CUSTOMER TYPE | G29: PRODUCT RISK | H29: TXN BEHAVIOUR | I29: ADVERSE INFO | J29: TOTAL SCORE | K29: TIER
A30: CUST001 | B30: Individual | C30: British | D30: Teacher | E30: 3 | F30: 0 | G30: 0 | H30: 0 | I30: 0 | J30: =SUM(E30:I30) -> 3 | K30: =IF(J30>=76,"EDD Urgent",IF(J30>=51,"EDD",IF(J30>=21,"CDD","SDD"))) -> SDD
A31: CUST002 | B31: Individual | C31: British | D31: Nurse | E31: 3 | F31: 0 | G31: 0 | H31: 0 | I31: 0 | J31: =SUM(E31:I31) -> 3 | K31: =IF(J31>=76,"EDD Urgent",IF(J31>=51,"EDD",IF(J31>=21,"CDD","SDD"))) -> SDD
A32: CUST003 | B32: Individual | C32: British | D32: Engineer | E32: 3 | F32: 0 | G32: 0 | H32: 0 | I32: 0 | J32: =SUM(E32:I32) -> 3 | K32: =IF(J32>=76,"EDD Urgent",IF(J32>=51,"EDD",IF(J32>=21,"CDD","SDD"))) -> SDD
A33: CUST004 | B33: Individual | C33: British | D33: Accountant | E33: 3 | F33: 0 | G33: 0 | H33: 0 | I33: 0 | J33: =SUM(E33:I33) -> 3 | K33: =IF(J33>=76,"EDD Urgent",IF(J33>=51,"EDD",IF(J33>=21,"CDD","SDD"))) -> SDD
A34: CUST005 | B34: Individual | C34: British | D34: Police Officer | E34: 3 | F34: 0 | G34: 0 | H34: 0 | I34: 0 | J34: =SUM(E34:I34) -> 3 | K34: =IF(J34>=76,"EDD Urgent",IF(J34>=51,"EDD",IF(J34>=21,"CDD","SDD"))) -> SDD
A35: CUST006 | B35: Individual | C35: British | D35: Retail Manager | E35: 3 | F35: 0 | G35: 0 | H35: 0 | I35: 0 | J35: =SUM(E35:I35) -> 3 | K35: =IF(J35>=76,"EDD Urgent",IF(J35>=51,"EDD",IF(J35>=21,"CDD","SDD"))) -> SDD
A36: CUST007 | B36: Individual | C36: British | D36: IT Analyst | E36: 3 | F36: 0 | G36: 12 | H36: 9 | I36: 0 | J36: =SUM(E36:I36) -> 24 | K36: =IF(J36>=76,"EDD Urgent",IF(J36>=51,"EDD",IF(J36>=21,"CDD","SDD"))) -> CDD
A37: CUST008 | B37: Individual | C37: British | D37: Social Worker | E37: 3 | F37: 0 | G37: 0 | H37: 0 | I37: 0 | J37: =SUM(E37:I37) -> 3 | K37: =IF(J37>=76,"EDD Urgent",IF(J37>=51,"EDD",IF(J37>=21,"CDD","SDD"))) -> SDD
A38: CUST009 | B38: Individual | C38: British | D38: Pharmacist | E38: 3 | F38: 0 | G38: 0 | H38: 0 | I38: 0 | J38: =SUM(E38:I38) -> 3 | K38: =IF(J38>=76,"EDD Urgent",IF(J38>=51,"EDD",IF(J38>=21,"CDD","SDD"))) -> SDD
A39: CUST010 | B39: Individual | C39: British | D39: Electrician | E39: 3 | F39: 0 | G39: 0 | H39: 0 | I39: 0 | J39: =SUM(E39:I39) -> 3 | K39: =IF(J39>=76,"EDD Urgent",IF(J39>=51,"EDD",IF(J39>=21,"CDD","SDD"))) -> SDD
A40: CUST011 | B40: Individual | C40: Indian | D40: IT Consultant | E40: 8 | F40: 7 | G40: 12 | H40: 3 | I40: 0 | J40: =SUM(E40:I40) -> 30 | K40: =IF(J40>=76,"EDD Urgent",IF(J40>=51,"EDD",IF(J40>=21,"CDD","SDD"))) -> CDD
A41: CUST012 | B41: Individual | C41: Nigerian | D41: Import/Export | E41: 16 | F41: 13 | G41: 12 | H41: 9 | I41: 5 | J41: =SUM(E41:I41) -> 55 | K41: =IF(J41>=76,"EDD Urgent",IF(J41>=51,"EDD",IF(J41>=21,"CDD","SDD"))) -> EDD
... A59: CUST030 | B59: Corporate | C59: UK Registered | D59: Import/Export Ltd | E59: 3 | F59: 17 | G59: 16 | H59: 9 | I59: 0 | J59: =SUM(E59:I59) -> 45 | K59: =IF(J59>=76,"EDD Urgent",IF(J59>=51,"EDD",IF(J59>=21,"CDD","SDD"))) -> CDD

Sheet TM_RULES_SUMMARY
A1: CALEDONIA BANK PLC — TRANSACTION MONITORING RULES SUMMARY
A2: Regulatory basis: MLR 2017 | JMLSG 2026 | POCA 2002 | FCA Financial Crime Guide | OFSI | 9 Active Rules | Last reviewed: 23/06/2026
A3: RULES OVERVIEW
A4: RULE_ID | B4: RULE_NAME | C4: TYPOLOGY | D4: TRIGGER CONDITIONS | E4: THRESHOLD | F4: PRIORITY | G4: REGULATORY BASIS | H4: ACTION REQUIRED | I4: ALERTS TRIGGERED FY2024 | J4: TRUE POSITIVE RATE
A5: TM-001 | B5: Structuring / Smurfing | C5: Money Laundering — Placement | D5: 3 or more cash deposits between £8,000-£9,999 within 30 days, or any single cash deposit of £9,500 or above | E5: £8,000 — £9,999 per transaction | F5: HIGH | G5: MLR 2017 Reg 28 | JMLSG Part I 6.13 | H5: Review transaction history. File SAR if no legitimate explanation. | I5: 2 | J5: 0.5
A6: TM-002 | B6: Rapid In-Out / Pass Through | C6: Money Laundering — Layering | D6: Credit >£10,000 followed by 80%+ debit within 48 hours | E6: >£10,000 credit, >80% debited within 48hrs | F6: HIGH | G6: MLR 2017 Reg 28 | JMLSG Part I 6.14 | H6: Freeze account pending investigation. Verify source of funds. | I6: 1 | J6: 1
A7: TM-003 | B7: High Risk Jurisdiction Transfer | C7: Money Laundering — Layering | D7: Any transaction to/from a FATF high-risk jurisdiction (call-for-action list) | E7: Any amount | F7: HIGH | G7: MLR 2017 Reg 33 | FATF Recommendations 18-21 | H7: Apply EDD. Verify purpose of transfer. Escalate to MLRO. | I7: 1 | J7: 1
A8: TM-004 | B8: Dormant Account Reactivation | C8: Money Laundering — Placement | D8: Any transaction >£5,000 on account dormant 12+ months | E8: >£5,000 on dormant account | F8: HIGH | G8: MLR 2017 Reg 28 | JMLSG Part I 6.22 | H8: Contact customer. Verify source of funds. Re-KYC required. | I8: 1 | J8: 1
A9: TM-005 | B9: PEP High Value Transaction | C9: Bribery / Corruption | D9: PEP customer transaction exceeding £50,000 | E9: >£50,000 for PEP customers | F9: HIGH | G9: MLR 2017 Reg 35 | JMLSG Part I 5.7 | H9: Senior management approval required. EDD review. Source of wealth verification. | I9: 1 | J9: Pending
A10: TM-006 | B10: Unusual Cash Intensity | C10: Money Laundering — Placement | D10: Total cash deposits exceed 200% of monthly expected turnover | E10: >200% of expected monthly turnover | F10: MEDIUM | G10: MLR 2017 Reg 28 | JMLSG Part II 4.3 | H10: Review cash source. Request business trading evidence. | I10: 1 | J10: 0
A11: TM-007 | B11: Round Tripping / Circular Funds | C11: Money Laundering — Layering | D11: Funds sent and returned between linked accounts within 14 days with <5% variance | E11: <5% variance on return within 14 days | F11: HIGH | G11: MLR 2017 Reg 28 | JMLSG Part I 6.15 | H11: Map linked accounts. Verify business purpose. Escalate if no legitimate reason. | I11: 1 | J11: 0
A12: TM-008 | B12: Sanctions Screening Hit | C12: Sanctions Evasion | D12: Counterparty country matches OFSI consolidated sanctions list | E12: Any amount to sanctioned jurisdiction | F12: CRITICAL | G12: POCA 2002 S.330 | Sanctions Act 2018 | OFSI Guidance | H12: Block transaction immediately. Freeze account. File SAR same day. Notify MLRO within 2 hours. | I12: 1 | J12: 1
A13: TM-009 | B13: Complex Corporate Structure | C13: Money Laundering — Layering | D13: Corporate credit >£50,000 followed by intercompany transfer where UBO not verified | E13: >£50,000 corporate credit, UBO unverified | F13: HIGH | G13: MLR 2017 Reg 28 | JMLSG Part I 5.3 | H13: Verify UBO and ownership structure. Map group entities. Escalate to MLRO if opacity persists. | I13: 1 | J13: Pending
A15: RULES PERFORMANCE SUMMARY — FY2024
A16: METRIC | B16: VALUE
A17: Total Active Rules | B17: =COUNTA(A5:A13) -> 9
A18: Total Alerts Generated FY2024 | B18: =SUM(I5:I13) -> 10
A19: Critical Priority Rules | B19: =COUNTIF(F5:F13,"CRITICAL") -> 1
A20: High Priority Rules | B20: =COUNTIF(F5:F13,"HIGH") -> 7
A21: Medium Priority Rules | B21: =COUNTIF(F5:F13,"MEDIUM") -> 1
A22: Overall True Positive Rate | B22: =ALERT_INVESTIGATION_LOG!C20/ALERT_INVESTIGATION_LOG!C19 -> 0.5
A23: SARs Filed | B23: =ALERT_INVESTIGATION_LOG!C24 -> 5
A24: Rules Triggered in FY2024 | B24: =COUNTIF(I5:I13,">0") -> 9
A26: NOTE: All TM rules are reviewed quarterly per JMLSG 2026 guidance. Rules are back-tested against 12 months of transaction data annually. CRITICAL rules (TM-008) trigger automatic account freeze per OFSI financial sanctions guidance. All SARs submitted to NCA within 7 working days per POCA 2002 Section 330.

Sheet SAR Report
A1: SUSPICIOUS ACTIVITY REPORT (SAR)
A2: CALEDONIA BANK PLC
A3: SUSPICIOUS ACTIVITY REPORT | SAR-2024-001 | Caledonia Bank plc | SAMPLE — SYNTHETIC DATA
A4: SAR Reference: SAR-2024-001
A5: Submitted to: National Crime Agency (NCA)
A6: Regulatory basis: POCA 2002 S.330 | MLR 2017 | JMLSG 2026
A8: Field | B8: Value
A9: SAR Reference | B9: SAR-2024-001
A10: Date of Submission | B10: 45366
A11: Submitted By | B11: AML Analyst — Financial Crime Team
A12: MLRO Sign-Off | B12: Chief Compliance Officer
A13: Alert Reference | B13: ALT001
A14: TM Rule Triggered | B14: TM-001 — Structuring / Smurfing
A15: Classification | B15: SAMPLE — SYNTHETIC DATA FOR DEMONSTRATION ONLY
A17: TIPPING OFF WARNING — POCA 2002 SECTION 333A
A18: It is a criminal offence to disclose to the subject of this report that a SAR has been filed. Penalty: up to 5 years imprisonment. DO NOT contact the customer.
A21: SECTION 1 — SUBJECT DETAILS
A22: Field | B22: Value
A23: Customer Reference | B23: CUST018
A24: Customer Name | B24: Redacted - available on secure system
A25: Customer Type | B25: Individual
A26: Occupation | B26: Market Trader
A27: Nationality | B27: British
A28: Country of Residence | B28: United Kingdom
A29: Account Status | B29: Active
A30: KYC Tier | B30: CDD (Customer Due Diligence)
A31: Risk Rating | B31: MEDIUM
A32: Monthly Expected Turnover | B32: £8,000
A33: Account Open Date | B33: =VLOOKUP(B23,CUSTOMER_PROFILES!A:J,10,FALSE) -> 43554
A34: Previous SARs | B34: None
A36: SECTION 2: SUSPICIOUS ACTIVITY
A38: The following suspicious activity was identified through the automated Transaction Monitoring system on 07 March 2024, triggering Rule TM-001 (Structuring / Smurfing).
A40: Transaction ID | B40: Date | C40: Type | D40: Amount | E40: Location | F40: Running Balance
A41: T051 | B41: 45354 | C41: Cash Deposit | D41: £9,500 | E41: Edinburgh Branch | F41: £9,500
A42: T052 | B42: 45355 | C42: Cash Deposit | D42: £9,200 | E42: Edinburgh Branch | F42: £18,700
A43: T053 | B43: 45358 | C43: Cash Deposit | D43: £9,800 | E43: Edinburgh Branch | F43: £28,500
A45: SUMMARY OF ACTIVITY:
A46: 1. Three cash deposits over 5 consecutive days totalling £28,500
A47: 2. All deposits just below £10,000 reporting threshold — classic structuring
A48: 3.Total represents 356% of monthly expected turnover of £8,000
...
